<?xml version="1.0" encoding="UTF-8"?>
<testng-results skipped="2" failed="1" total="21" passed="18">
  <reporter-output>
  </reporter-output>
  <suite name="Main Test Suite" duration-ms="14871" started-at="2014-04-29T03:39:04Z" finished-at="2014-04-29T03:39:19Z">
    <groups>
    </groups>
    <test name="Main Test Group" duration-ms="14871" started-at="2014-04-29T03:39:04Z" finished-at="2014-04-29T03:39:19Z">
      <class name="qa.tests.FailTest">
        <test-method status="PASS" signature="setName()[pri:0, instance:qa.tests.FailTest@4cdbe50f]" test-instance-name="d0582064" name="setName" is-config="true" duration-ms="5" started-at="2014-04-28T20:39:04Z" finished-at="2014-04-28T20:39:04Z">
          <reporter-output>
          </reporter-output>
        </test-method> <!-- setName -->
        <test-method status="PASS" signature="setsSuccess()[pri:0, instance:qa.tests.FailTest@4cdbe50f]" test-instance-name="d0582064" name="setsSuccess" duration-ms="2277" started-at="2014-04-28T20:39:04Z" finished-at="2014-04-28T20:39:06Z">
          <reporter-output>
          </reporter-output>
        </test-method> <!-- setsSuccess -->
        <test-method status="PASS" signature="setName()[pri:0, instance:qa.tests.FailTest@4cdbe50f]" test-instance-name="d0582064" name="setName" is-config="true" duration-ms="1" started-at="2014-04-28T20:39:06Z" finished-at="2014-04-28T20:39:06Z">
          <reporter-output>
          </reporter-output>
        </test-method> <!-- setName -->
        <test-method status="FAIL" signature="showFailure()[pri:0, instance:qa.tests.FailTest@4cdbe50f]" test-instance-name="d0582064" name="showFailure" duration-ms="2663" started-at="2014-04-28T20:39:06Z" finished-at="2014-04-28T20:39:09Z">
          <exception class="java.lang.AssertionError">
            <message>
              <![CDATA[null]]>
            </message>
            <full-stacktrace>
              <![CDATA[java.lang.AssertionError: null
	at org.testng.Assert.fail(Assert.java:94)
	at org.testng.Assert.fail(Assert.java:101)
	at qa.tests.FailTest.showFailure(FailTest.java:40)
	at sun.reflect.NativeMethodAccessorImpl.invoke0(Native Method)
	at sun.reflect.NativeMethodAccessorImpl.invoke(NativeMethodAccessorImpl.java:62)
	at sun.reflect.DelegatingMethodAccessorImpl.invoke(DelegatingMethodAccessorImpl.java:43)
	at java.lang.reflect.Method.invoke(Method.java:483)
	at org.testng.internal.MethodInvocationHelper.invokeMethod(MethodInvocationHelper.java:84)
	at org.testng.internal.Invoker.invokeMethod(Invoker.java:714)
	at org.testng.internal.Invoker.invokeTestMethod(Invoker.java:901)
	at org.testng.internal.Invoker.invokeTestMethods(Invoker.java:1231)
	at org.testng.internal.TestMethodWorker.invokeTestMethods(TestMethodWorker.java:127)
	at org.testng.internal.TestMethodWorker.run(TestMethodWorker.java:111)
	at java.util.concurrent.ThreadPoolExecutor.runWorker(ThreadPoolExecutor.java:1142)
	at java.util.concurrent.ThreadPoolExecutor$Worker.run(ThreadPoolExecutor.java:617)
	at java.lang.Thread.run(Thread.java:745)
]]>
            </full-stacktrace>
          </exception> <!-- java.lang.AssertionError -->
          <reporter-output>
          </reporter-output>
        </test-method> <!-- showFailure -->
      </class> <!-- qa.tests.FailTest -->
      <class name="qa.tests.BeforeTestSkip">
        <test-method status="PASS" signature="setName()[pri:0, instance:qa.tests.BeforeTestSkip@66d33a]" test-instance-name="ff5234d7" name="setName" is-config="true" duration-ms="5" started-at="2014-04-28T20:39:04Z" finished-at="2014-04-28T20:39:04Z">
          <reporter-output>
          </reporter-output>
        </test-method> <!-- setName -->
        <test-method status="SKIP" signature="setUp()[pri:0, instance:qa.tests.BeforeTestSkip@66d33a]" test-instance-name="ff5234d7" name="setUp" is-config="true" duration-ms="0" started-at="2014-04-28T20:39:04Z" finished-at="2014-04-28T20:39:04Z">
          <exception class="org.testng.SkipException">
            <message>
              <![CDATA[SkipException thrown in setUp method.]]>
            </message>
            <full-stacktrace>
              <![CDATA[org.testng.SkipException: SkipException thrown in setUp method.
	at qa.tests.BeforeTestSkip.setUp(BeforeTestSkip.java:24)
	at sun.reflect.NativeMethodAccessorImpl.invoke0(Native Method)
	at sun.reflect.NativeMethodAccessorImpl.invoke(NativeMethodAccessorImpl.java:62)
	at sun.reflect.DelegatingMethodAccessorImpl.invoke(DelegatingMethodAccessorImpl.java:43)
	at java.lang.reflect.Method.invoke(Method.java:483)
	at org.testng.internal.MethodInvocationHelper.invokeMethod(MethodInvocationHelper.java:84)
	at org.testng.internal.Invoker.invokeConfigurationMethod(Invoker.java:564)
	at org.testng.internal.Invoker.invokeConfigurations(Invoker.java:213)
	at org.testng.internal.Invoker.invokeMethod(Invoker.java:653)
	at org.testng.internal.Invoker.invokeTestMethod(Invoker.java:901)
	at org.testng.internal.Invoker.invokeTestMethods(Invoker.java:1231)
	at org.testng.internal.TestMethodWorker.invokeTestMethods(TestMethodWorker.java:127)
	at org.testng.internal.TestMethodWorker.run(TestMethodWorker.java:111)
	at java.util.concurrent.ThreadPoolExecutor.runWorker(ThreadPoolExecutor.java:1142)
	at java.util.concurrent.ThreadPoolExecutor$Worker.run(ThreadPoolExecutor.java:617)
	at java.lang.Thread.run(Thread.java:745)
]]>
            </full-stacktrace>
          </exception> <!-- org.testng.SkipException -->
          <reporter-output>
          </reporter-output>
        </test-method> <!-- setUp -->
        <test-method status="SKIP" signature="arraysFailures_3()[pri:0, instance:qa.tests.BeforeTestSkip@66d33a]" test-instance-name="ff5234d7" name="arraysFailures_3" duration-ms="0" started-at="2014-04-28T20:39:04Z" finished-at="2014-04-28T20:39:04Z">
          <reporter-output>
          </reporter-output>
        </test-method> <!-- arraysFailures_3 -->
      </class> <!-- qa.tests.BeforeTestSkip -->
      <class name="qa.tests.AssertTests1">
        <test-method status="PASS" signature="setName()[pri:0, instance:qa.tests.AssertTests1@7cf10a6f]" test-instance-name="03587128" name="setName" is-config="true" duration-ms="5" started-at="2014-04-28T20:39:04Z" finished-at="2014-04-28T20:39:04Z">
          <reporter-output>
          </reporter-output>
        </test-method> <!-- setName -->
        <test-method status="PASS" signature="arraysFailures_1()[pri:0, instance:qa.tests.AssertTests1@7cf10a6f]" test-instance-name="03587128" name="arraysFailures_1" duration-ms="2722" started-at="2014-04-28T20:39:04Z" finished-at="2014-04-28T20:39:07Z">
          <exception class="java.lang.AssertionError">
            <message>
              <![CDATA[ expected [[J@4acf825] but found [[I@3b6520b1]]]>
            </message>
            <full-stacktrace>
              <![CDATA[java.lang.AssertionError:  expected [[J@4acf825] but found [[I@3b6520b1]
	at org.testng.Assert.fail(Assert.java:94)
	at org.testng.Assert.failNotEquals(Assert.java:494)
	at org.testng.Assert.assertArrayEquals(Assert.java:144)
	at org.testng.Assert.assertEquals(Assert.java:117)
	at org.testng.Assert.assertEquals(Assert.java:165)
	at qa.tests.AssertTests1.arraysFailures_1(AssertTests1.java:61)
	at sun.reflect.NativeMethodAccessorImpl.invoke0(Native Method)
	at sun.reflect.NativeMethodAccessorImpl.invoke(NativeMethodAccessorImpl.java:62)
	at sun.reflect.DelegatingMethodAccessorImpl.invoke(DelegatingMethodAccessorImpl.java:43)
	at java.lang.reflect.Method.invoke(Method.java:483)
	at org.testng.internal.MethodInvocationHelper.invokeMethod(MethodInvocationHelper.java:84)
	at org.testng.internal.Invoker.invokeMethod(Invoker.java:714)
	at org.testng.internal.Invoker.invokeTestMethod(Invoker.java:901)
	at org.testng.internal.Invoker.invokeTestMethods(Invoker.java:1231)
	at org.testng.internal.TestMethodWorker.invokeTestMethods(TestMethodWorker.java:127)
	at org.testng.internal.TestMethodWorker.run(TestMethodWorker.java:111)
	at java.util.concurrent.ThreadPoolExecutor.runWorker(ThreadPoolExecutor.java:1142)
	at java.util.concurrent.ThreadPoolExecutor$Worker.run(ThreadPoolExecutor.java:617)
	at java.lang.Thread.run(Thread.java:745)
]]>
            </full-stacktrace>
          </exception> <!-- java.lang.AssertionError -->
          <reporter-output>
          </reporter-output>
        </test-method> <!-- arraysFailures_1 -->
        <test-method status="PASS" signature="arraysFailures_2()[pri:0, instance:qa.tests.AssertTests1@7cf10a6f]" test-instance-name="03587128" name="arraysFailures_2" duration-ms="1096" started-at="2014-04-28T20:39:07Z" finished-at="2014-04-28T20:39:08Z">
          <exception class="java.lang.AssertionError">
            <message>
              <![CDATA[expected [1] but found [[I@1693b921]]]>
            </message>
            <full-stacktrace>
              <![CDATA[java.lang.AssertionError: expected [1] but found [[I@1693b921]
	at org.testng.Assert.fail(Assert.java:94)
	at org.testng.Assert.failNotEquals(Assert.java:494)
	at org.testng.Assert.assertEquals(Assert.java:123)
	at org.testng.Assert.assertEquals(Assert.java:165)
	at qa.tests.AssertTests1.arraysFailures_2(AssertTests1.java:68)
	at sun.reflect.NativeMethodAccessorImpl.invoke0(Native Method)
	at sun.reflect.NativeMethodAccessorImpl.invoke(NativeMethodAccessorImpl.java:62)
	at sun.reflect.DelegatingMethodAccessorImpl.invoke(DelegatingMethodAccessorImpl.java:43)
	at java.lang.reflect.Method.invoke(Method.java:483)
	at org.testng.internal.MethodInvocationHelper.invokeMethod(MethodInvocationHelper.java:84)
	at org.testng.internal.Invoker.invokeMethod(Invoker.java:714)
	at org.testng.internal.Invoker.invokeTestMethod(Invoker.java:901)
	at org.testng.internal.Invoker.invokeTestMethods(Invoker.java:1231)
	at org.testng.internal.TestMethodWorker.invokeTestMethods(TestMethodWorker.java:127)
	at org.testng.internal.TestMethodWorker.run(TestMethodWorker.java:111)
	at java.util.concurrent.ThreadPoolExecutor.runWorker(ThreadPoolExecutor.java:1142)
	at java.util.concurrent.ThreadPoolExecutor$Worker.run(ThreadPoolExecutor.java:617)
	at java.lang.Thread.run(Thread.java:745)
]]>
            </full-stacktrace>
          </exception> <!-- java.lang.AssertionError -->
          <reporter-output>
          </reporter-output>
        </test-method> <!-- arraysFailures_2 -->
        <test-method status="PASS" signature="setName()[pri:0, instance:qa.tests.AssertTests1@7cf10a6f]" test-instance-name="03587128" name="setName" is-config="true" duration-ms="0" started-at="2014-04-28T20:39:07Z" finished-at="2014-04-28T20:39:07Z">
          <reporter-output>
          </reporter-output>
        </test-method> <!-- setName -->
        <test-method status="PASS" signature="arraysFailures_3()[pri:0, instance:qa.tests.AssertTests1@7cf10a6f]" test-instance-name="03587128" name="arraysFailures_3" duration-ms="2592" started-at="2014-04-28T20:39:08Z" finished-at="2014-04-28T20:39:10Z">
          <exception class="java.lang.AssertionError">
            <message>
              <![CDATA[expected [[J@40ef2ba5] but found [1]]]>
            </message>
            <full-stacktrace>
              <![CDATA[java.lang.AssertionError: expected [[J@40ef2ba5] but found [1]
	at org.testng.Assert.fail(Assert.java:94)
	at org.testng.Assert.failNotEquals(Assert.java:494)
	at org.testng.Assert.assertArrayEquals(Assert.java:155)
	at org.testng.Assert.assertEquals(Assert.java:117)
	at org.testng.Assert.assertEquals(Assert.java:165)
	at qa.tests.AssertTests1.arraysFailures_3(AssertTests1.java:75)
	at sun.reflect.NativeMethodAccessorImpl.invoke0(Native Method)
	at sun.reflect.NativeMethodAccessorImpl.invoke(NativeMethodAccessorImpl.java:62)
	at sun.reflect.DelegatingMethodAccessorImpl.invoke(DelegatingMethodAccessorImpl.java:43)
	at java.lang.reflect.Method.invoke(Method.java:483)
	at org.testng.internal.MethodInvocationHelper.invokeMethod(MethodInvocationHelper.java:84)
	at org.testng.internal.Invoker.invokeMethod(Invoker.java:714)
	at org.testng.internal.Invoker.invokeTestMethod(Invoker.java:901)
	at org.testng.internal.Invoker.invokeTestMethods(Invoker.java:1231)
	at org.testng.internal.TestMethodWorker.invokeTestMethods(TestMethodWorker.java:127)
	at org.testng.internal.TestMethodWorker.run(TestMethodWorker.java:111)
	at java.util.concurrent.ThreadPoolExecutor.runWorker(ThreadPoolExecutor.java:1142)
	at java.util.concurrent.ThreadPoolExecutor$Worker.run(ThreadPoolExecutor.java:617)
	at java.lang.Thread.run(Thread.java:745)
]]>
            </full-stacktrace>
          </exception> <!-- java.lang.AssertionError -->
          <reporter-output>
          </reporter-output>
        </test-method> <!-- arraysFailures_3 -->
        <test-method status="PASS" signature="setName()[pri:0, instance:qa.tests.AssertTests1@7cf10a6f]" test-instance-name="03587128" name="setName" is-config="true" duration-ms="0" started-at="2014-04-28T20:39:08Z" finished-at="2014-04-28T20:39:08Z">
          <reporter-output>
          </reporter-output>
        </test-method> <!-- setName -->
        <test-method status="PASS" signature="setName()[pri:0, instance:qa.tests.AssertTests1@7cf10a6f]" test-instance-name="03587128" name="setName" is-config="true" duration-ms="0" started-at="2014-04-28T20:39:10Z" finished-at="2014-04-28T20:39:10Z">
          <reporter-output>
          </reporter-output>
        </test-method> <!-- setName -->
        <test-method status="PASS" signature="intArray_Issue4()[pri:0, instance:qa.tests.AssertTests1@7cf10a6f]" test-instance-name="03587128" name="intArray_Issue4" duration-ms="537" started-at="2014-04-28T20:39:10Z" finished-at="2014-04-28T20:39:11Z">
          <reporter-output>
          </reporter-output>
        </test-method> <!-- intArray_Issue4 -->
        <test-method status="PASS" signature="setName()[pri:0, instance:qa.tests.AssertTests1@7cf10a6f]" test-instance-name="03587128" name="setName" is-config="true" duration-ms="1" started-at="2014-04-28T20:39:11Z" finished-at="2014-04-28T20:39:11Z">
          <reporter-output>
          </reporter-output>
        </test-method> <!-- setName -->
        <test-method status="PASS" signature="int_Integer_Arrays()[pri:0, instance:qa.tests.AssertTests1@7cf10a6f]" test-instance-name="03587128" name="int_Integer_Arrays" duration-ms="904" started-at="2014-04-28T20:39:11Z" finished-at="2014-04-28T20:39:12Z">
          <reporter-output>
          </reporter-output>
        </test-method> <!-- int_Integer_Arrays -->
        <test-method status="PASS" signature="setName()[pri:0, instance:qa.tests.AssertTests1@7cf10a6f]" test-instance-name="03587128" name="setName" is-config="true" duration-ms="1" started-at="2014-04-28T20:39:12Z" finished-at="2014-04-28T20:39:12Z">
          <reporter-output>
          </reporter-output>
        </test-method> <!-- setName -->
        <test-method status="PASS" signature="noOrderFailure()[pri:0, instance:qa.tests.AssertTests1@7cf10a6f]" test-instance-name="03587128" name="noOrderFailure" duration-ms="715" started-at="2014-04-28T20:39:12Z" finished-at="2014-04-28T20:39:13Z">
          <exception class="java.lang.AssertionError">
            <message>
              <![CDATA[Arrays not equal: [a, b, b] and [a, a, b]]]>
            </message>
            <full-stacktrace>
              <![CDATA[java.lang.AssertionError: Arrays not equal: [a, b, b] and [a, a, b]
	at org.testng.Assert.fail(Assert.java:94)
	at org.testng.Assert.failAssertNoEqual(Assert.java:713)
	at org.testng.Assert.assertEqualsNoOrder(Assert.java:703)
	at org.testng.Assert.assertEqualsNoOrder(Assert.java:735)
	at qa.tests.AssertTests1.noOrderFailure(AssertTests1.java:36)
	at sun.reflect.NativeMethodAccessorImpl.invoke0(Native Method)
	at sun.reflect.NativeMethodAccessorImpl.invoke(NativeMethodAccessorImpl.java:62)
	at sun.reflect.DelegatingMethodAccessorImpl.invoke(DelegatingMethodAccessorImpl.java:43)
	at java.lang.reflect.Method.invoke(Method.java:483)
	at org.testng.internal.MethodInvocationHelper.invokeMethod(MethodInvocationHelper.java:84)
	at org.testng.internal.Invoker.invokeMethod(Invoker.java:714)
	at org.testng.internal.Invoker.invokeTestMethod(Invoker.java:901)
	at org.testng.internal.Invoker.invokeTestMethods(Invoker.java:1231)
	at org.testng.internal.TestMethodWorker.invokeTestMethods(TestMethodWorker.java:127)
	at org.testng.internal.TestMethodWorker.run(TestMethodWorker.java:111)
	at java.util.concurrent.ThreadPoolExecutor.runWorker(ThreadPoolExecutor.java:1142)
	at java.util.concurrent.ThreadPoolExecutor$Worker.run(ThreadPoolExecutor.java:617)
	at java.lang.Thread.run(Thread.java:745)
]]>
            </full-stacktrace>
          </exception> <!-- java.lang.AssertionError -->
          <reporter-output>
          </reporter-output>
        </test-method> <!-- noOrderFailure -->
        <test-method status="PASS" signature="setName()[pri:0, instance:qa.tests.AssertTests1@7cf10a6f]" test-instance-name="03587128" name="setName" is-config="true" duration-ms="0" started-at="2014-04-28T20:39:13Z" finished-at="2014-04-28T20:39:13Z">
          <reporter-output>
          </reporter-output>
        </test-method> <!-- setName -->
        <test-method status="PASS" signature="noOrderSuccess()[pri:0, instance:qa.tests.AssertTests1@7cf10a6f]" test-instance-name="03587128" name="noOrderSuccess" duration-ms="2712" started-at="2014-04-28T20:39:13Z" finished-at="2014-04-28T20:39:15Z">
          <reporter-output>
          </reporter-output>
        </test-method> <!-- noOrderSuccess -->
        <test-method status="PASS" signature="setName()[pri:0, instance:qa.tests.AssertTests1@7cf10a6f]" test-instance-name="03587128" name="setName" is-config="true" duration-ms="1" started-at="2014-04-28T20:39:15Z" finished-at="2014-04-28T20:39:15Z">
          <reporter-output>
          </reporter-output>
        </test-method> <!-- setName -->
        <test-method status="PASS" signature="setsSuccess()[pri:0, instance:qa.tests.AssertTests1@7cf10a6f]" test-instance-name="03587128" name="setsSuccess" duration-ms="803" started-at="2014-04-28T20:39:15Z" finished-at="2014-04-28T20:39:16Z">
          <reporter-output>
          </reporter-output>
        </test-method> <!-- setsSuccess -->
      </class> <!-- qa.tests.AssertTests1 -->
      <class name="qa.tests.SkipTest">
        <test-method status="PASS" signature="setName()[pri:0, instance:qa.tests.SkipTest@256216b3]" test-instance-name="7c82c68d" name="setName" is-config="true" duration-ms="5" started-at="2014-04-28T20:39:04Z" finished-at="2014-04-28T20:39:04Z">
          <reporter-output>
          </reporter-output>
        </test-method> <!-- setName -->
        <test-method status="PASS" signature="setsSuccess()[pri:0, instance:qa.tests.SkipTest@256216b3]" test-instance-name="7c82c68d" name="setsSuccess" duration-ms="2235" started-at="2014-04-28T20:39:04Z" finished-at="2014-04-28T20:39:06Z">
          <reporter-output>
          </reporter-output>
        </test-method> <!-- setsSuccess -->
        <test-method status="SKIP" signature="testSkipException()[pri:0, instance:qa.tests.SkipTest@256216b3]" test-instance-name="7c82c68d" name="testSkipException" duration-ms="1940" started-at="2014-04-28T20:39:06Z" finished-at="2014-04-28T20:39:08Z">
          <exception class="org.testng.SkipException">
            <message>
              <![CDATA[Testing SkipException effect on report output.]]>
            </message>
            <full-stacktrace>
              <![CDATA[org.testng.SkipException: Testing SkipException effect on report output.
	at qa.tests.SkipTest.testSkipException(SkipTest.java:26)
	at sun.reflect.NativeMethodAccessorImpl.invoke0(Native Method)
	at sun.reflect.NativeMethodAccessorImpl.invoke(NativeMethodAccessorImpl.java:62)
	at sun.reflect.DelegatingMethodAccessorImpl.invoke(DelegatingMethodAccessorImpl.java:43)
	at java.lang.reflect.Method.invoke(Method.java:483)
	at org.testng.internal.MethodInvocationHelper.invokeMethod(MethodInvocationHelper.java:84)
	at org.testng.internal.Invoker.invokeMethod(Invoker.java:714)
	at org.testng.internal.Invoker.invokeTestMethod(Invoker.java:901)
	at org.testng.internal.Invoker.invokeTestMethods(Invoker.java:1231)
	at org.testng.internal.TestMethodWorker.invokeTestMethods(TestMethodWorker.java:127)
	at org.testng.internal.TestMethodWorker.run(TestMethodWorker.java:111)
	at java.util.concurrent.ThreadPoolExecutor.runWorker(ThreadPoolExecutor.java:1142)
	at java.util.concurrent.ThreadPoolExecutor$Worker.run(ThreadPoolExecutor.java:617)
	at java.lang.Thread.run(Thread.java:745)
]]>
            </full-stacktrace>
          </exception> <!-- org.testng.SkipException -->
          <reporter-output>
          </reporter-output>
        </test-method> <!-- testSkipException -->
        <test-method status="PASS" signature="setName()[pri:0, instance:qa.tests.SkipTest@256216b3]" test-instance-name="7c82c68d" name="setName" is-config="true" duration-ms="0" started-at="2014-04-28T20:39:06Z" finished-at="2014-04-28T20:39:06Z">
          <reporter-output>
          </reporter-output>
        </test-method> <!-- setName -->
      </class> <!-- qa.tests.SkipTest -->
      <class name="qa.tests.AssertTests2">
        <test-method status="PASS" signature="setName()[pri:0, instance:qa.tests.AssertTests2@1fbc7afb]" test-instance-name="10a179eb" name="setName" is-config="true" duration-ms="5" started-at="2014-04-28T20:39:04Z" finished-at="2014-04-28T20:39:04Z">
          <reporter-output>
          </reporter-output>
        </test-method> <!-- setName -->
        <test-method status="PASS" signature="arraysFailures_1()[pri:0, instance:qa.tests.AssertTests2@1fbc7afb]" test-instance-name="10a179eb" name="arraysFailures_1" duration-ms="1481" started-at="2014-04-28T20:39:04Z" finished-at="2014-04-28T20:39:06Z">
          <exception class="java.lang.AssertionError">
            <message>
              <![CDATA[ expected [[J@715749bf] but found [[I@7c226110]]]>
            </message>
            <full-stacktrace>
              <![CDATA[java.lang.AssertionError:  expected [[J@715749bf] but found [[I@7c226110]
	at org.testng.Assert.fail(Assert.java:94)
	at org.testng.Assert.failNotEquals(Assert.java:494)
	at org.testng.Assert.assertArrayEquals(Assert.java:144)
	at org.testng.Assert.assertEquals(Assert.java:117)
	at org.testng.Assert.assertEquals(Assert.java:165)
	at qa.tests.AssertTests2.arraysFailures_1(AssertTests2.java:60)
	at sun.reflect.NativeMethodAccessorImpl.invoke0(Native Method)
	at sun.reflect.NativeMethodAccessorImpl.invoke(NativeMethodAccessorImpl.java:62)
	at sun.reflect.DelegatingMethodAccessorImpl.invoke(DelegatingMethodAccessorImpl.java:43)
	at java.lang.reflect.Method.invoke(Method.java:483)
	at org.testng.internal.MethodInvocationHelper.invokeMethod(MethodInvocationHelper.java:84)
	at org.testng.internal.Invoker.invokeMethod(Invoker.java:714)
	at org.testng.internal.Invoker.invokeTestMethod(Invoker.java:901)
	at org.testng.internal.Invoker.invokeTestMethods(Invoker.java:1231)
	at org.testng.internal.TestMethodWorker.invokeTestMethods(TestMethodWorker.java:127)
	at org.testng.internal.TestMethodWorker.run(TestMethodWorker.java:111)
	at java.util.concurrent.ThreadPoolExecutor.runWorker(ThreadPoolExecutor.java:1142)
	at java.util.concurrent.ThreadPoolExecutor$Worker.run(ThreadPoolExecutor.java:617)
	at java.lang.Thread.run(Thread.java:745)
]]>
            </full-stacktrace>
          </exception> <!-- java.lang.AssertionError -->
          <reporter-output>
          </reporter-output>
        </test-method> <!-- arraysFailures_1 -->
        <test-method status="PASS" signature="setName()[pri:0, instance:qa.tests.AssertTests2@1fbc7afb]" test-instance-name="10a179eb" name="setName" is-config="true" duration-ms="0" started-at="2014-04-28T20:39:06Z" finished-at="2014-04-28T20:39:06Z">
          <reporter-output>
          </reporter-output>
        </test-method> <!-- setName -->
        <test-method status="PASS" signature="arraysFailures_2()[pri:0, instance:qa.tests.AssertTests2@1fbc7afb]" test-instance-name="10a179eb" name="arraysFailures_2" duration-ms="2838" started-at="2014-04-28T20:39:06Z" finished-at="2014-04-28T20:39:08Z">
          <exception class="java.lang.AssertionError">
            <message>
              <![CDATA[expected [1] but found [[I@50f5f0b4]]]>
            </message>
            <full-stacktrace>
              <![CDATA[java.lang.AssertionError: expected [1] but found [[I@50f5f0b4]
	at org.testng.Assert.fail(Assert.java:94)
	at org.testng.Assert.failNotEquals(Assert.java:494)
	at org.testng.Assert.assertEquals(Assert.java:123)
	at org.testng.Assert.assertEquals(Assert.java:165)
	at qa.tests.AssertTests2.arraysFailures_2(AssertTests2.java:67)
	at sun.reflect.NativeMethodAccessorImpl.invoke0(Native Method)
	at sun.reflect.NativeMethodAccessorImpl.invoke(NativeMethodAccessorImpl.java:62)
	at sun.reflect.DelegatingMethodAccessorImpl.invoke(DelegatingMethodAccessorImpl.java:43)
	at java.lang.reflect.Method.invoke(Method.java:483)
	at org.testng.internal.MethodInvocationHelper.invokeMethod(MethodInvocationHelper.java:84)
	at org.testng.internal.Invoker.invokeMethod(Invoker.java:714)
	at org.testng.internal.Invoker.invokeTestMethod(Invoker.java:901)
	at org.testng.internal.Invoker.invokeTestMethods(Invoker.java:1231)
	at org.testng.internal.TestMethodWorker.invokeTestMethods(TestMethodWorker.java:127)
	at org.testng.internal.TestMethodWorker.run(TestMethodWorker.java:111)
	at java.util.concurrent.ThreadPoolExecutor.runWorker(ThreadPoolExecutor.java:1142)
	at java.util.concurrent.ThreadPoolExecutor$Worker.run(ThreadPoolExecutor.java:617)
	at java.lang.Thread.run(Thread.java:745)
]]>
            </full-stacktrace>
          </exception> <!-- java.lang.AssertionError -->
          <reporter-output>
          </reporter-output>
        </test-method> <!-- arraysFailures_2 -->
        <test-method status="PASS" signature="setName()[pri:0, instance:qa.tests.AssertTests2@1fbc7afb]" test-instance-name="10a179eb" name="setName" is-config="true" duration-ms="1" started-at="2014-04-28T20:39:08Z" finished-at="2014-04-28T20:39:08Z">
          <reporter-output>
          </reporter-output>
        </test-method> <!-- setName -->
        <test-method status="PASS" signature="arraysFailures_3()[pri:0, instance:qa.tests.AssertTests2@1fbc7afb]" test-instance-name="10a179eb" name="arraysFailures_3" duration-ms="1665" started-at="2014-04-28T20:39:08Z" finished-at="2014-04-28T20:39:10Z">
          <exception class="java.lang.AssertionError">
            <message>
              <![CDATA[expected [[J@2fb48181] but found [1]]]>
            </message>
            <full-stacktrace>
              <![CDATA[java.lang.AssertionError: expected [[J@2fb48181] but found [1]
	at org.testng.Assert.fail(Assert.java:94)
	at org.testng.Assert.failNotEquals(Assert.java:494)
	at org.testng.Assert.assertArrayEquals(Assert.java:155)
	at org.testng.Assert.assertEquals(Assert.java:117)
	at org.testng.Assert.assertEquals(Assert.java:165)
	at qa.tests.AssertTests2.arraysFailures_3(AssertTests2.java:74)
	at sun.reflect.NativeMethodAccessorImpl.invoke0(Native Method)
	at sun.reflect.NativeMethodAccessorImpl.invoke(NativeMethodAccessorImpl.java:62)
	at sun.reflect.DelegatingMethodAccessorImpl.invoke(DelegatingMethodAccessorImpl.java:43)
	at java.lang.reflect.Method.invoke(Method.java:483)
	at org.testng.internal.MethodInvocationHelper.invokeMethod(MethodInvocationHelper.java:84)
	at org.testng.internal.Invoker.invokeMethod(Invoker.java:714)
	at org.testng.internal.Invoker.invokeTestMethod(Invoker.java:901)
	at org.testng.internal.Invoker.invokeTestMethods(Invoker.java:1231)
	at org.testng.internal.TestMethodWorker.invokeTestMethods(TestMethodWorker.java:127)
	at org.testng.internal.TestMethodWorker.run(TestMethodWorker.java:111)
	at java.util.concurrent.ThreadPoolExecutor.runWorker(ThreadPoolExecutor.java:1142)
	at java.util.concurrent.ThreadPoolExecutor$Worker.run(ThreadPoolExecutor.java:617)
	at java.lang.Thread.run(Thread.java:745)
]]>
            </full-stacktrace>
          </exception> <!-- java.lang.AssertionError -->
          <reporter-output>
          </reporter-output>
        </test-method> <!-- arraysFailures_3 -->
        <test-method status="PASS" signature="setName()[pri:0, instance:qa.tests.AssertTests2@1fbc7afb]" test-instance-name="10a179eb" name="setName" is-config="true" duration-ms="0" started-at="2014-04-28T20:39:10Z" finished-at="2014-04-28T20:39:10Z">
          <reporter-output>
          </reporter-output>
        </test-method> <!-- setName -->
        <test-method status="PASS" signature="intArray_Issue4()[pri:0, instance:qa.tests.AssertTests2@1fbc7afb]" test-instance-name="10a179eb" name="intArray_Issue4" duration-ms="1703" started-at="2014-04-28T20:39:10Z" finished-at="2014-04-28T20:39:12Z">
          <reporter-output>
          </reporter-output>
        </test-method> <!-- intArray_Issue4 -->
        <test-method status="PASS" signature="setName()[pri:0, instance:qa.tests.AssertTests2@1fbc7afb]" test-instance-name="10a179eb" name="setName" is-config="true" duration-ms="1" started-at="2014-04-28T20:39:12Z" finished-at="2014-04-28T20:39:12Z">
          <reporter-output>
          </reporter-output>
        </test-method> <!-- setName -->
        <test-method status="PASS" signature="int_Integer_Arrays()[pri:0, instance:qa.tests.AssertTests2@1fbc7afb]" test-instance-name="10a179eb" name="int_Integer_Arrays" duration-ms="699" started-at="2014-04-28T20:39:12Z" finished-at="2014-04-28T20:39:12Z">
          <reporter-output>
          </reporter-output>
        </test-method> <!-- int_Integer_Arrays -->
        <test-method status="PASS" signature="setName()[pri:0, instance:qa.tests.AssertTests2@1fbc7afb]" test-instance-name="10a179eb" name="setName" is-config="true" duration-ms="1" started-at="2014-04-28T20:39:12Z" finished-at="2014-04-28T20:39:12Z">
          <reporter-output>
          </reporter-output>
        </test-method> <!-- setName -->
        <test-method status="PASS" signature="noOrderFailure()[pri:0, instance:qa.tests.AssertTests2@1fbc7afb]" test-instance-name="10a179eb" name="noOrderFailure" duration-ms="1505" started-at="2014-04-28T20:39:12Z" finished-at="2014-04-28T20:39:14Z">
          <exception class="java.lang.AssertionError">
            <message>
              <![CDATA[Arrays not equal: [a, b, b] and [a, a, b]]]>
            </message>
            <full-stacktrace>
              <![CDATA[java.lang.AssertionError: Arrays not equal: [a, b, b] and [a, a, b]
	at org.testng.Assert.fail(Assert.java:94)
	at org.testng.Assert.failAssertNoEqual(Assert.java:713)
	at org.testng.Assert.assertEqualsNoOrder(Assert.java:703)
	at org.testng.Assert.assertEqualsNoOrder(Assert.java:735)
	at qa.tests.AssertTests2.noOrderFailure(AssertTests2.java:35)
	at sun.reflect.NativeMethodAccessorImpl.invoke0(Native Method)
	at sun.reflect.NativeMethodAccessorImpl.invoke(NativeMethodAccessorImpl.java:62)
	at sun.reflect.DelegatingMethodAccessorImpl.invoke(DelegatingMethodAccessorImpl.java:43)
	at java.lang.reflect.Method.invoke(Method.java:483)
	at org.testng.internal.MethodInvocationHelper.invokeMethod(MethodInvocationHelper.java:84)
	at org.testng.internal.Invoker.invokeMethod(Invoker.java:714)
	at org.testng.internal.Invoker.invokeTestMethod(Invoker.java:901)
	at org.testng.internal.Invoker.invokeTestMethods(Invoker.java:1231)
	at org.testng.internal.TestMethodWorker.invokeTestMethods(TestMethodWorker.java:127)
	at org.testng.internal.TestMethodWorker.run(TestMethodWorker.java:111)
	at java.util.concurrent.ThreadPoolExecutor.runWorker(ThreadPoolExecutor.java:1142)
	at java.util.concurrent.ThreadPoolExecutor$Worker.run(ThreadPoolExecutor.java:617)
	at java.lang.Thread.run(Thread.java:745)
]]>
            </full-stacktrace>
          </exception> <!-- java.lang.AssertionError -->
          <reporter-output>
          </reporter-output>
        </test-method> <!-- noOrderFailure -->
        <test-method status="PASS" signature="setName()[pri:0, instance:qa.tests.AssertTests2@1fbc7afb]" test-instance-name="10a179eb" name="setName" is-config="true" duration-ms="0" started-at="2014-04-28T20:39:14Z" finished-at="2014-04-28T20:39:14Z">
          <reporter-output>
          </reporter-output>
        </test-method> <!-- setName -->
        <test-method status="PASS" signature="noOrderSuccess()[pri:0, instance:qa.tests.AssertTests2@1fbc7afb]" test-instance-name="10a179eb" name="noOrderSuccess" duration-ms="2382" started-at="2014-04-28T20:39:14Z" finished-at="2014-04-28T20:39:16Z">
          <reporter-output>
          </reporter-output>
        </test-method> <!-- noOrderSuccess -->
        <test-method status="PASS" signature="setName()[pri:0, instance:qa.tests.AssertTests2@1fbc7afb]" test-instance-name="10a179eb" name="setName" is-config="true" duration-ms="1" started-at="2014-04-28T20:39:16Z" finished-at="2014-04-28T20:39:16Z">
          <reporter-output>
          </reporter-output>
        </test-method> <!-- setName -->
        <test-method status="PASS" signature="setsSuccess()[pri:0, instance:qa.tests.AssertTests2@1fbc7afb]" test-instance-name="10a179eb" name="setsSuccess" duration-ms="2575" started-at="2014-04-28T20:39:16Z" finished-at="2014-04-28T20:39:19Z">
          <reporter-output>
          </reporter-output>
        </test-method> <!-- setsSuccess -->
      </class> <!-- qa.tests.AssertTests2 -->
    </test> <!-- Main Test Group -->
  </suite> <!-- Main Test Suite -->
</testng-results>
