<?xml version="1.0" encoding="UTF-8"?>
<testng-results skipped="2" failed="1" total="21" passed="18">
  <reporter-output>
  </reporter-output>
  <suite name="Main Test Suite" duration-ms="18814" started-at="2014-04-29T01:34:35Z" finished-at="2014-04-29T01:34:54Z">
    <groups>
    </groups>
    <test name="Main Test Group" duration-ms="18814" started-at="2014-04-29T01:34:35Z" finished-at="2014-04-29T01:34:54Z">
      <class name="qa.tests.FailTest">
        <test-method status="PASS" signature="setsSuccess()[pri:0, instance:qa.tests.FailTest@6833ce2c]" name="setsSuccess" duration-ms="1409" started-at="2014-04-28T18:34:35Z" finished-at="2014-04-28T18:34:37Z">
          <reporter-output>
          </reporter-output>
        </test-method> <!-- setsSuccess -->
        <test-method status="FAIL" signature="showFailure()[pri:0, instance:qa.tests.FailTest@6833ce2c]" name="showFailure" duration-ms="701" started-at="2014-04-28T18:34:37Z" finished-at="2014-04-28T18:34:37Z">
          <exception class="java.lang.AssertionError">
            <message>
              <![CDATA[null]]>
            </message>
            <full-stacktrace>
              <![CDATA[java.lang.AssertionError: null
	at org.testng.Assert.fail(Assert.java:94)
	at org.testng.Assert.fail(Assert.java:101)
	at qa.tests.FailTest.showFailure(FailTest.java:37)
	at sun.reflect.NativeMethodAccessorImpl.invoke0(Native Method)
	at sun.reflect.NativeMethodAccessorImpl.invoke(NativeMethodAccessorImpl.java:62)
	at sun.reflect.DelegatingMethodAccessorImpl.invoke(DelegatingMethodAccessorImpl.java:43)
	at java.lang.reflect.Method.invoke(Method.java:483)
	at org.testng.internal.MethodInvocationHelper.invokeMethod(MethodInvocationHelper.java:84)
	at org.testng.internal.Invoker.invokeMethod(Invoker.java:714)
	at org.testng.internal.Invoker.invokeTestMethod(Invoker.java:901)
	at org.testng.internal.Invoker.invokeTestMethods(Invoker.java:1231)
	at org.testng.internal.TestMethodWorker.invokeTestMethods(TestMethodWorker.java:127)
	at org.testng.internal.TestMethodWorker.run(TestMethodWorker.java:111)
	at java.util.concurrent.ThreadPoolExecutor.runWorker(ThreadPoolExecutor.java:1142)
	at java.util.concurrent.ThreadPoolExecutor$Worker.run(ThreadPoolExecutor.java:617)
	at java.lang.Thread.run(Thread.java:745)
]]>
            </full-stacktrace>
          </exception> <!-- java.lang.AssertionError -->
          <reporter-output>
          </reporter-output>
        </test-method> <!-- showFailure -->
      </class> <!-- qa.tests.FailTest -->
      <class name="qa.tests.BeforeTestSkip">
        <test-method status="SKIP" signature="setUp()[pri:0, instance:qa.tests.BeforeTestSkip@71c7db30]" name="setUp" is-config="true" duration-ms="0" started-at="2014-04-28T18:34:35Z" finished-at="2014-04-28T18:34:35Z">
          <exception class="org.testng.SkipException">
            <message>
              <![CDATA[SkipException thrown in setUp method.]]>
            </message>
            <full-stacktrace>
              <![CDATA[org.testng.SkipException: SkipException thrown in setUp method.
	at qa.tests.BeforeTestSkip.setUp(BeforeTestSkip.java:21)
	at sun.reflect.NativeMethodAccessorImpl.invoke0(Native Method)
	at sun.reflect.NativeMethodAccessorImpl.invoke(NativeMethodAccessorImpl.java:62)
	at sun.reflect.DelegatingMethodAccessorImpl.invoke(DelegatingMethodAccessorImpl.java:43)
	at java.lang.reflect.Method.invoke(Method.java:483)
	at org.testng.internal.MethodInvocationHelper.invokeMethod(MethodInvocationHelper.java:84)
	at org.testng.internal.Invoker.invokeConfigurationMethod(Invoker.java:564)
	at org.testng.internal.Invoker.invokeConfigurations(Invoker.java:213)
	at org.testng.internal.Invoker.invokeMethod(Invoker.java:653)
	at org.testng.internal.Invoker.invokeTestMethod(Invoker.java:901)
	at org.testng.internal.Invoker.invokeTestMethods(Invoker.java:1231)
	at org.testng.internal.TestMethodWorker.invokeTestMethods(TestMethodWorker.java:127)
	at org.testng.internal.TestMethodWorker.run(TestMethodWorker.java:111)
	at java.util.concurrent.ThreadPoolExecutor.runWorker(ThreadPoolExecutor.java:1142)
	at java.util.concurrent.ThreadPoolExecutor$Worker.run(ThreadPoolExecutor.java:617)
	at java.lang.Thread.run(Thread.java:745)
]]>
            </full-stacktrace>
          </exception> <!-- org.testng.SkipException -->
          <reporter-output>
          </reporter-output>
        </test-method> <!-- setUp -->
        <test-method status="SKIP" signature="arraysFailures_3()[pri:0, instance:qa.tests.BeforeTestSkip@71c7db30]" name="arraysFailures_3" duration-ms="1" started-at="2014-04-28T18:34:35Z" finished-at="2014-04-28T18:34:35Z">
          <reporter-output>
          </reporter-output>
        </test-method> <!-- arraysFailures_3 -->
      </class> <!-- qa.tests.BeforeTestSkip -->
      <class name="qa.tests.AssertTests1">
        <test-method status="PASS" signature="arraysFailures_1()[pri:0, instance:qa.tests.AssertTests1@3c5a99da]" name="arraysFailures_1" duration-ms="2539" started-at="2014-04-28T18:34:35Z" finished-at="2014-04-28T18:34:38Z">
          <exception class="java.lang.AssertionError">
            <message>
              <![CDATA[ expected [[J@1b06d36a] but found [[I@4d7e3f28]]]>
            </message>
            <full-stacktrace>
              <![CDATA[java.lang.AssertionError:  expected [[J@1b06d36a] but found [[I@4d7e3f28]
	at org.testng.Assert.fail(Assert.java:94)
	at org.testng.Assert.failNotEquals(Assert.java:494)
	at org.testng.Assert.assertArrayEquals(Assert.java:144)
	at org.testng.Assert.assertEquals(Assert.java:117)
	at org.testng.Assert.assertEquals(Assert.java:165)
	at qa.tests.AssertTests1.arraysFailures_1(AssertTests1.java:53)
	at sun.reflect.NativeMethodAccessorImpl.invoke0(Native Method)
	at sun.reflect.NativeMethodAccessorImpl.invoke(NativeMethodAccessorImpl.java:62)
	at sun.reflect.DelegatingMethodAccessorImpl.invoke(DelegatingMethodAccessorImpl.java:43)
	at java.lang.reflect.Method.invoke(Method.java:483)
	at org.testng.internal.MethodInvocationHelper.invokeMethod(MethodInvocationHelper.java:84)
	at org.testng.internal.Invoker.invokeMethod(Invoker.java:714)
	at org.testng.internal.Invoker.invokeTestMethod(Invoker.java:901)
	at org.testng.internal.Invoker.invokeTestMethods(Invoker.java:1231)
	at org.testng.internal.TestMethodWorker.invokeTestMethods(TestMethodWorker.java:127)
	at org.testng.internal.TestMethodWorker.run(TestMethodWorker.java:111)
	at java.util.concurrent.ThreadPoolExecutor.runWorker(ThreadPoolExecutor.java:1142)
	at java.util.concurrent.ThreadPoolExecutor$Worker.run(ThreadPoolExecutor.java:617)
	at java.lang.Thread.run(Thread.java:745)
]]>
            </full-stacktrace>
          </exception> <!-- java.lang.AssertionError -->
          <reporter-output>
          </reporter-output>
        </test-method> <!-- arraysFailures_1 -->
        <test-method status="PASS" signature="arraysFailures_2()[pri:0, instance:qa.tests.AssertTests1@3c5a99da]" name="arraysFailures_2" duration-ms="2646" started-at="2014-04-28T18:34:38Z" finished-at="2014-04-28T18:34:40Z">
          <exception class="java.lang.AssertionError">
            <message>
              <![CDATA[expected [1] but found [[I@290337bb]]]>
            </message>
            <full-stacktrace>
              <![CDATA[java.lang.AssertionError: expected [1] but found [[I@290337bb]
	at org.testng.Assert.fail(Assert.java:94)
	at org.testng.Assert.failNotEquals(Assert.java:494)
	at org.testng.Assert.assertEquals(Assert.java:123)
	at org.testng.Assert.assertEquals(Assert.java:165)
	at qa.tests.AssertTests1.arraysFailures_2(AssertTests1.java:60)
	at sun.reflect.NativeMethodAccessorImpl.invoke0(Native Method)
	at sun.reflect.NativeMethodAccessorImpl.invoke(NativeMethodAccessorImpl.java:62)
	at sun.reflect.DelegatingMethodAccessorImpl.invoke(DelegatingMethodAccessorImpl.java:43)
	at java.lang.reflect.Method.invoke(Method.java:483)
	at org.testng.internal.MethodInvocationHelper.invokeMethod(MethodInvocationHelper.java:84)
	at org.testng.internal.Invoker.invokeMethod(Invoker.java:714)
	at org.testng.internal.Invoker.invokeTestMethod(Invoker.java:901)
	at org.testng.internal.Invoker.invokeTestMethods(Invoker.java:1231)
	at org.testng.internal.TestMethodWorker.invokeTestMethods(TestMethodWorker.java:127)
	at org.testng.internal.TestMethodWorker.run(TestMethodWorker.java:111)
	at java.util.concurrent.ThreadPoolExecutor.runWorker(ThreadPoolExecutor.java:1142)
	at java.util.concurrent.ThreadPoolExecutor$Worker.run(ThreadPoolExecutor.java:617)
	at java.lang.Thread.run(Thread.java:745)
]]>
            </full-stacktrace>
          </exception> <!-- java.lang.AssertionError -->
          <reporter-output>
          </reporter-output>
        </test-method> <!-- arraysFailures_2 -->
        <test-method status="PASS" signature="arraysFailures_3()[pri:0, instance:qa.tests.AssertTests1@3c5a99da]" name="arraysFailures_3" duration-ms="2406" started-at="2014-04-28T18:34:40Z" finished-at="2014-04-28T18:34:43Z">
          <exception class="java.lang.AssertionError">
            <message>
              <![CDATA[expected [[J@3808d4b3] but found [1]]]>
            </message>
            <full-stacktrace>
              <![CDATA[java.lang.AssertionError: expected [[J@3808d4b3] but found [1]
	at org.testng.Assert.fail(Assert.java:94)
	at org.testng.Assert.failNotEquals(Assert.java:494)
	at org.testng.Assert.assertArrayEquals(Assert.java:155)
	at org.testng.Assert.assertEquals(Assert.java:117)
	at org.testng.Assert.assertEquals(Assert.java:165)
	at qa.tests.AssertTests1.arraysFailures_3(AssertTests1.java:67)
	at sun.reflect.NativeMethodAccessorImpl.invoke0(Native Method)
	at sun.reflect.NativeMethodAccessorImpl.invoke(NativeMethodAccessorImpl.java:62)
	at sun.reflect.DelegatingMethodAccessorImpl.invoke(DelegatingMethodAccessorImpl.java:43)
	at java.lang.reflect.Method.invoke(Method.java:483)
	at org.testng.internal.MethodInvocationHelper.invokeMethod(MethodInvocationHelper.java:84)
	at org.testng.internal.Invoker.invokeMethod(Invoker.java:714)
	at org.testng.internal.Invoker.invokeTestMethod(Invoker.java:901)
	at org.testng.internal.Invoker.invokeTestMethods(Invoker.java:1231)
	at org.testng.internal.TestMethodWorker.invokeTestMethods(TestMethodWorker.java:127)
	at org.testng.internal.TestMethodWorker.run(TestMethodWorker.java:111)
	at java.util.concurrent.ThreadPoolExecutor.runWorker(ThreadPoolExecutor.java:1142)
	at java.util.concurrent.ThreadPoolExecutor$Worker.run(ThreadPoolExecutor.java:617)
	at java.lang.Thread.run(Thread.java:745)
]]>
            </full-stacktrace>
          </exception> <!-- java.lang.AssertionError -->
          <reporter-output>
          </reporter-output>
        </test-method> <!-- arraysFailures_3 -->
        <test-method status="PASS" signature="intArray_Issue4()[pri:0, instance:qa.tests.AssertTests1@3c5a99da]" name="intArray_Issue4" duration-ms="1913" started-at="2014-04-28T18:34:43Z" finished-at="2014-04-28T18:34:45Z">
          <reporter-output>
          </reporter-output>
        </test-method> <!-- intArray_Issue4 -->
        <test-method status="PASS" signature="int_Integer_Arrays()[pri:0, instance:qa.tests.AssertTests1@3c5a99da]" name="int_Integer_Arrays" duration-ms="2465" started-at="2014-04-28T18:34:45Z" finished-at="2014-04-28T18:34:47Z">
          <reporter-output>
          </reporter-output>
        </test-method> <!-- int_Integer_Arrays -->
        <test-method status="PASS" signature="noOrderFailure()[pri:0, instance:qa.tests.AssertTests1@3c5a99da]" name="noOrderFailure" duration-ms="2418" started-at="2014-04-28T18:34:47Z" finished-at="2014-04-28T18:34:50Z">
          <exception class="java.lang.AssertionError">
            <message>
              <![CDATA[Arrays not equal: [a, b, b] and [a, a, b]]]>
            </message>
            <full-stacktrace>
              <![CDATA[java.lang.AssertionError: Arrays not equal: [a, b, b] and [a, a, b]
	at org.testng.Assert.fail(Assert.java:94)
	at org.testng.Assert.failAssertNoEqual(Assert.java:713)
	at org.testng.Assert.assertEqualsNoOrder(Assert.java:703)
	at org.testng.Assert.assertEqualsNoOrder(Assert.java:735)
	at qa.tests.AssertTests1.noOrderFailure(AssertTests1.java:28)
	at sun.reflect.NativeMethodAccessorImpl.invoke0(Native Method)
	at sun.reflect.NativeMethodAccessorImpl.invoke(NativeMethodAccessorImpl.java:62)
	at sun.reflect.DelegatingMethodAccessorImpl.invoke(DelegatingMethodAccessorImpl.java:43)
	at java.lang.reflect.Method.invoke(Method.java:483)
	at org.testng.internal.MethodInvocationHelper.invokeMethod(MethodInvocationHelper.java:84)
	at org.testng.internal.Invoker.invokeMethod(Invoker.java:714)
	at org.testng.internal.Invoker.invokeTestMethod(Invoker.java:901)
	at org.testng.internal.Invoker.invokeTestMethods(Invoker.java:1231)
	at org.testng.internal.TestMethodWorker.invokeTestMethods(TestMethodWorker.java:127)
	at org.testng.internal.TestMethodWorker.run(TestMethodWorker.java:111)
	at java.util.concurrent.ThreadPoolExecutor.runWorker(ThreadPoolExecutor.java:1142)
	at java.util.concurrent.ThreadPoolExecutor$Worker.run(ThreadPoolExecutor.java:617)
	at java.lang.Thread.run(Thread.java:745)
]]>
            </full-stacktrace>
          </exception> <!-- java.lang.AssertionError -->
          <reporter-output>
          </reporter-output>
        </test-method> <!-- noOrderFailure -->
        <test-method status="PASS" signature="noOrderSuccess()[pri:0, instance:qa.tests.AssertTests1@3c5a99da]" name="noOrderSuccess" duration-ms="1791" started-at="2014-04-28T18:34:50Z" finished-at="2014-04-28T18:34:51Z">
          <reporter-output>
          </reporter-output>
        </test-method> <!-- noOrderSuccess -->
        <test-method status="PASS" signature="setsSuccess()[pri:0, instance:qa.tests.AssertTests1@3c5a99da]" name="setsSuccess" duration-ms="2622" started-at="2014-04-28T18:34:51Z" finished-at="2014-04-28T18:34:54Z">
          <reporter-output>
          </reporter-output>
        </test-method> <!-- setsSuccess -->
      </class> <!-- qa.tests.AssertTests1 -->
      <class name="qa.tests.SkipTest">
        <test-method status="PASS" signature="setsSuccess()[pri:0, instance:qa.tests.SkipTest@47f37ef1]" name="setsSuccess" duration-ms="1477" started-at="2014-04-28T18:34:35Z" finished-at="2014-04-28T18:34:37Z">
          <reporter-output>
          </reporter-output>
        </test-method> <!-- setsSuccess -->
        <test-method status="SKIP" signature="testSkipException()[pri:0, instance:qa.tests.SkipTest@47f37ef1]" name="testSkipException" duration-ms="1734" started-at="2014-04-28T18:34:37Z" finished-at="2014-04-28T18:34:38Z">
          <exception class="org.testng.SkipException">
            <message>
              <![CDATA[Testing SkipException effect on report output.]]>
            </message>
            <full-stacktrace>
              <![CDATA[org.testng.SkipException: Testing SkipException effect on report output.
	at qa.tests.SkipTest.testSkipException(SkipTest.java:21)
	at sun.reflect.NativeMethodAccessorImpl.invoke0(Native Method)
	at sun.reflect.NativeMethodAccessorImpl.invoke(NativeMethodAccessorImpl.java:62)
	at sun.reflect.DelegatingMethodAccessorImpl.invoke(DelegatingMethodAccessorImpl.java:43)
	at java.lang.reflect.Method.invoke(Method.java:483)
	at org.testng.internal.MethodInvocationHelper.invokeMethod(MethodInvocationHelper.java:84)
	at org.testng.internal.Invoker.invokeMethod(Invoker.java:714)
	at org.testng.internal.Invoker.invokeTestMethod(Invoker.java:901)
	at org.testng.internal.Invoker.invokeTestMethods(Invoker.java:1231)
	at org.testng.internal.TestMethodWorker.invokeTestMethods(TestMethodWorker.java:127)
	at org.testng.internal.TestMethodWorker.run(TestMethodWorker.java:111)
	at java.util.concurrent.ThreadPoolExecutor.runWorker(ThreadPoolExecutor.java:1142)
	at java.util.concurrent.ThreadPoolExecutor$Worker.run(ThreadPoolExecutor.java:617)
	at java.lang.Thread.run(Thread.java:745)
]]>
            </full-stacktrace>
          </exception> <!-- org.testng.SkipException -->
          <reporter-output>
          </reporter-output>
        </test-method> <!-- testSkipException -->
      </class> <!-- qa.tests.SkipTest -->
      <class name="qa.tests.AssertTests2">
        <test-method status="PASS" signature="arraysFailures_1()[pri:0, instance:qa.tests.AssertTests2@5a01ccaa]" name="arraysFailures_1" duration-ms="627" started-at="2014-04-28T18:34:35Z" finished-at="2014-04-28T18:34:36Z">
          <exception class="java.lang.AssertionError">
            <message>
              <![CDATA[ expected [[J@6c46f0ec] but found [[I@23ba0f83]]]>
            </message>
            <full-stacktrace>
              <![CDATA[java.lang.AssertionError:  expected [[J@6c46f0ec] but found [[I@23ba0f83]
	at org.testng.Assert.fail(Assert.java:94)
	at org.testng.Assert.failNotEquals(Assert.java:494)
	at org.testng.Assert.assertArrayEquals(Assert.java:144)
	at org.testng.Assert.assertEquals(Assert.java:117)
	at org.testng.Assert.assertEquals(Assert.java:165)
	at qa.tests.AssertTests2.arraysFailures_1(AssertTests2.java:56)
	at sun.reflect.NativeMethodAccessorImpl.invoke0(Native Method)
	at sun.reflect.NativeMethodAccessorImpl.invoke(NativeMethodAccessorImpl.java:62)
	at sun.reflect.DelegatingMethodAccessorImpl.invoke(DelegatingMethodAccessorImpl.java:43)
	at java.lang.reflect.Method.invoke(Method.java:483)
	at org.testng.internal.MethodInvocationHelper.invokeMethod(MethodInvocationHelper.java:84)
	at org.testng.internal.Invoker.invokeMethod(Invoker.java:714)
	at org.testng.internal.Invoker.invokeTestMethod(Invoker.java:901)
	at org.testng.internal.Invoker.invokeTestMethods(Invoker.java:1231)
	at org.testng.internal.TestMethodWorker.invokeTestMethods(TestMethodWorker.java:127)
	at org.testng.internal.TestMethodWorker.run(TestMethodWorker.java:111)
	at java.util.concurrent.ThreadPoolExecutor.runWorker(ThreadPoolExecutor.java:1142)
	at java.util.concurrent.ThreadPoolExecutor$Worker.run(ThreadPoolExecutor.java:617)
	at java.lang.Thread.run(Thread.java:745)
]]>
            </full-stacktrace>
          </exception> <!-- java.lang.AssertionError -->
          <reporter-output>
          </reporter-output>
        </test-method> <!-- arraysFailures_1 -->
        <test-method status="PASS" signature="arraysFailures_2()[pri:0, instance:qa.tests.AssertTests2@5a01ccaa]" name="arraysFailures_2" duration-ms="1064" started-at="2014-04-28T18:34:36Z" finished-at="2014-04-28T18:34:37Z">
          <exception class="java.lang.AssertionError">
            <message>
              <![CDATA[expected [1] but found [[I@1c3d56bb]]]>
            </message>
            <full-stacktrace>
              <![CDATA[java.lang.AssertionError: expected [1] but found [[I@1c3d56bb]
	at org.testng.Assert.fail(Assert.java:94)
	at org.testng.Assert.failNotEquals(Assert.java:494)
	at org.testng.Assert.assertEquals(Assert.java:123)
	at org.testng.Assert.assertEquals(Assert.java:165)
	at qa.tests.AssertTests2.arraysFailures_2(AssertTests2.java:63)
	at sun.reflect.NativeMethodAccessorImpl.invoke0(Native Method)
	at sun.reflect.NativeMethodAccessorImpl.invoke(NativeMethodAccessorImpl.java:62)
	at sun.reflect.DelegatingMethodAccessorImpl.invoke(DelegatingMethodAccessorImpl.java:43)
	at java.lang.reflect.Method.invoke(Method.java:483)
	at org.testng.internal.MethodInvocationHelper.invokeMethod(MethodInvocationHelper.java:84)
	at org.testng.internal.Invoker.invokeMethod(Invoker.java:714)
	at org.testng.internal.Invoker.invokeTestMethod(Invoker.java:901)
	at org.testng.internal.Invoker.invokeTestMethods(Invoker.java:1231)
	at org.testng.internal.TestMethodWorker.invokeTestMethods(TestMethodWorker.java:127)
	at org.testng.internal.TestMethodWorker.run(TestMethodWorker.java:111)
	at java.util.concurrent.ThreadPoolExecutor.runWorker(ThreadPoolExecutor.java:1142)
	at java.util.concurrent.ThreadPoolExecutor$Worker.run(ThreadPoolExecutor.java:617)
	at java.lang.Thread.run(Thread.java:745)
]]>
            </full-stacktrace>
          </exception> <!-- java.lang.AssertionError -->
          <reporter-output>
          </reporter-output>
        </test-method> <!-- arraysFailures_2 -->
        <test-method status="PASS" signature="arraysFailures_3()[pri:0, instance:qa.tests.AssertTests2@5a01ccaa]" name="arraysFailures_3" duration-ms="756" started-at="2014-04-28T18:34:37Z" finished-at="2014-04-28T18:34:38Z">
          <exception class="java.lang.AssertionError">
            <message>
              <![CDATA[expected [[J@3492cd30] but found [1]]]>
            </message>
            <full-stacktrace>
              <![CDATA[java.lang.AssertionError: expected [[J@3492cd30] but found [1]
	at org.testng.Assert.fail(Assert.java:94)
	at org.testng.Assert.failNotEquals(Assert.java:494)
	at org.testng.Assert.assertArrayEquals(Assert.java:155)
	at org.testng.Assert.assertEquals(Assert.java:117)
	at org.testng.Assert.assertEquals(Assert.java:165)
	at qa.tests.AssertTests2.arraysFailures_3(AssertTests2.java:70)
	at sun.reflect.NativeMethodAccessorImpl.invoke0(Native Method)
	at sun.reflect.NativeMethodAccessorImpl.invoke(NativeMethodAccessorImpl.java:62)
	at sun.reflect.DelegatingMethodAccessorImpl.invoke(DelegatingMethodAccessorImpl.java:43)
	at java.lang.reflect.Method.invoke(Method.java:483)
	at org.testng.internal.MethodInvocationHelper.invokeMethod(MethodInvocationHelper.java:84)
	at org.testng.internal.Invoker.invokeMethod(Invoker.java:714)
	at org.testng.internal.Invoker.invokeTestMethod(Invoker.java:901)
	at org.testng.internal.Invoker.invokeTestMethods(Invoker.java:1231)
	at org.testng.internal.TestMethodWorker.invokeTestMethods(TestMethodWorker.java:127)
	at org.testng.internal.TestMethodWorker.run(TestMethodWorker.java:111)
	at java.util.concurrent.ThreadPoolExecutor.runWorker(ThreadPoolExecutor.java:1142)
	at java.util.concurrent.ThreadPoolExecutor$Worker.run(ThreadPoolExecutor.java:617)
	at java.lang.Thread.run(Thread.java:745)
]]>
            </full-stacktrace>
          </exception> <!-- java.lang.AssertionError -->
          <reporter-output>
          </reporter-output>
        </test-method> <!-- arraysFailures_3 -->
        <test-method status="PASS" signature="intArray_Issue4()[pri:0, instance:qa.tests.AssertTests2@5a01ccaa]" name="intArray_Issue4" duration-ms="1214" started-at="2014-04-28T18:34:38Z" finished-at="2014-04-28T18:34:39Z">
          <reporter-output>
          </reporter-output>
        </test-method> <!-- intArray_Issue4 -->
        <test-method status="PASS" signature="int_Integer_Arrays()[pri:0, instance:qa.tests.AssertTests2@5a01ccaa]" name="int_Integer_Arrays" duration-ms="723" started-at="2014-04-28T18:34:39Z" finished-at="2014-04-28T18:34:40Z">
          <reporter-output>
          </reporter-output>
        </test-method> <!-- int_Integer_Arrays -->
        <test-method status="PASS" signature="noOrderFailure()[pri:0, instance:qa.tests.AssertTests2@5a01ccaa]" name="noOrderFailure" duration-ms="2889" started-at="2014-04-28T18:34:40Z" finished-at="2014-04-28T18:34:43Z">
          <exception class="java.lang.AssertionError">
            <message>
              <![CDATA[Arrays not equal: [a, b, b] and [a, a, b]]]>
            </message>
            <full-stacktrace>
              <![CDATA[java.lang.AssertionError: Arrays not equal: [a, b, b] and [a, a, b]
	at org.testng.Assert.fail(Assert.java:94)
	at org.testng.Assert.failAssertNoEqual(Assert.java:713)
	at org.testng.Assert.assertEqualsNoOrder(Assert.java:703)
	at org.testng.Assert.assertEqualsNoOrder(Assert.java:735)
	at qa.tests.AssertTests2.noOrderFailure(AssertTests2.java:31)
	at sun.reflect.NativeMethodAccessorImpl.invoke0(Native Method)
	at sun.reflect.NativeMethodAccessorImpl.invoke(NativeMethodAccessorImpl.java:62)
	at sun.reflect.DelegatingMethodAccessorImpl.invoke(DelegatingMethodAccessorImpl.java:43)
	at java.lang.reflect.Method.invoke(Method.java:483)
	at org.testng.internal.MethodInvocationHelper.invokeMethod(MethodInvocationHelper.java:84)
	at org.testng.internal.Invoker.invokeMethod(Invoker.java:714)
	at org.testng.internal.Invoker.invokeTestMethod(Invoker.java:901)
	at org.testng.internal.Invoker.invokeTestMethods(Invoker.java:1231)
	at org.testng.internal.TestMethodWorker.invokeTestMethods(TestMethodWorker.java:127)
	at org.testng.internal.TestMethodWorker.run(TestMethodWorker.java:111)
	at java.util.concurrent.ThreadPoolExecutor.runWorker(ThreadPoolExecutor.java:1142)
	at java.util.concurrent.ThreadPoolExecutor$Worker.run(ThreadPoolExecutor.java:617)
	at java.lang.Thread.run(Thread.java:745)
]]>
            </full-stacktrace>
          </exception> <!-- java.lang.AssertionError -->
          <reporter-output>
          </reporter-output>
        </test-method> <!-- noOrderFailure -->
        <test-method status="PASS" signature="noOrderSuccess()[pri:0, instance:qa.tests.AssertTests2@5a01ccaa]" name="noOrderSuccess" duration-ms="676" started-at="2014-04-28T18:34:43Z" finished-at="2014-04-28T18:34:43Z">
          <reporter-output>
          </reporter-output>
        </test-method> <!-- noOrderSuccess -->
        <test-method status="PASS" signature="setsSuccess()[pri:0, instance:qa.tests.AssertTests2@5a01ccaa]" name="setsSuccess" duration-ms="1580" started-at="2014-04-28T18:34:43Z" finished-at="2014-04-28T18:34:45Z">
          <reporter-output>
          </reporter-output>
        </test-method> <!-- setsSuccess -->
      </class> <!-- qa.tests.AssertTests2 -->
    </test> <!-- Main Test Group -->
  </suite> <!-- Main Test Suite -->
</testng-results>
