<?xml version="1.0" encoding="UTF-8"?>
<testng-results skipped="0" failed="0" total="16" passed="16">
  <reporter-output>
  </reporter-output>
  <suite name="Main Test Suite" duration-ms="15074" started-at="2014-04-28T15:02:37Z" finished-at="2014-04-28T15:02:52Z">
    <groups>
    </groups>
    <test name="Main Test Group" duration-ms="15074" started-at="2014-04-28T15:02:37Z" finished-at="2014-04-28T15:02:52Z">
      <class name="qa.tests.AssertTests1">
        <test-method status="PASS" signature="arraysFailures_1()[pri:0, instance:qa.tests.AssertTests1@546a03af]" name="arraysFailures_1" duration-ms="2375" started-at="2014-04-28T08:02:37Z" finished-at="2014-04-28T08:02:39Z">
          <exception class="java.lang.AssertionError">
            <message>
              <![CDATA[ expected [[J@616f7563] but found [[I@70175e5d]]]>
            </message>
            <full-stacktrace>
              <![CDATA[java.lang.AssertionError:  expected [[J@616f7563] but found [[I@70175e5d]
	at org.testng.Assert.fail(Assert.java:94)
	at org.testng.Assert.failNotEquals(Assert.java:494)
	at org.testng.Assert.assertArrayEquals(Assert.java:144)
	at org.testng.Assert.assertEquals(Assert.java:117)
	at org.testng.Assert.assertEquals(Assert.java:165)
	at qa.tests.AssertTests1.arraysFailures_1(AssertTests1.java:53)
	at sun.reflect.NativeMethodAccessorImpl.invoke0(Native Method)
	at sun.reflect.NativeMethodAccessorImpl.invoke(NativeMethodAccessorImpl.java:62)
	at sun.reflect.DelegatingMethodAccessorImpl.invoke(DelegatingMethodAccessorImpl.java:43)
	at java.lang.reflect.Method.invoke(Method.java:483)
	at org.testng.internal.MethodInvocationHelper.invokeMethod(MethodInvocationHelper.java:84)
	at org.testng.internal.Invoker.invokeMethod(Invoker.java:714)
	at org.testng.internal.Invoker.invokeTestMethod(Invoker.java:901)
	at org.testng.internal.Invoker.invokeTestMethods(Invoker.java:1231)
	at org.testng.internal.TestMethodWorker.invokeTestMethods(TestMethodWorker.java:127)
	at org.testng.internal.TestMethodWorker.run(TestMethodWorker.java:111)
	at java.util.concurrent.ThreadPoolExecutor.runWorker(ThreadPoolExecutor.java:1142)
	at java.util.concurrent.ThreadPoolExecutor$Worker.run(ThreadPoolExecutor.java:617)
	at java.lang.Thread.run(Thread.java:745)
]]>
            </full-stacktrace>
          </exception> <!-- java.lang.AssertionError -->
          <reporter-output>
          </reporter-output>
        </test-method> <!-- arraysFailures_1 -->
        <test-method status="PASS" signature="arraysFailures_2()[pri:0, instance:qa.tests.AssertTests1@546a03af]" name="arraysFailures_2" duration-ms="1995" started-at="2014-04-28T08:02:39Z" finished-at="2014-04-28T08:02:41Z">
          <exception class="java.lang.AssertionError">
            <message>
              <![CDATA[expected [1] but found [[I@19354406]]]>
            </message>
            <full-stacktrace>
              <![CDATA[java.lang.AssertionError: expected [1] but found [[I@19354406]
	at org.testng.Assert.fail(Assert.java:94)
	at org.testng.Assert.failNotEquals(Assert.java:494)
	at org.testng.Assert.assertEquals(Assert.java:123)
	at org.testng.Assert.assertEquals(Assert.java:165)
	at qa.tests.AssertTests1.arraysFailures_2(AssertTests1.java:60)
	at sun.reflect.NativeMethodAccessorImpl.invoke0(Native Method)
	at sun.reflect.NativeMethodAccessorImpl.invoke(NativeMethodAccessorImpl.java:62)
	at sun.reflect.DelegatingMethodAccessorImpl.invoke(DelegatingMethodAccessorImpl.java:43)
	at java.lang.reflect.Method.invoke(Method.java:483)
	at org.testng.internal.MethodInvocationHelper.invokeMethod(MethodInvocationHelper.java:84)
	at org.testng.internal.Invoker.invokeMethod(Invoker.java:714)
	at org.testng.internal.Invoker.invokeTestMethod(Invoker.java:901)
	at org.testng.internal.Invoker.invokeTestMethods(Invoker.java:1231)
	at org.testng.internal.TestMethodWorker.invokeTestMethods(TestMethodWorker.java:127)
	at org.testng.internal.TestMethodWorker.run(TestMethodWorker.java:111)
	at java.util.concurrent.ThreadPoolExecutor.runWorker(ThreadPoolExecutor.java:1142)
	at java.util.concurrent.ThreadPoolExecutor$Worker.run(ThreadPoolExecutor.java:617)
	at java.lang.Thread.run(Thread.java:745)
]]>
            </full-stacktrace>
          </exception> <!-- java.lang.AssertionError -->
          <reporter-output>
          </reporter-output>
        </test-method> <!-- arraysFailures_2 -->
        <test-method status="PASS" signature="arraysFailures_3()[pri:0, instance:qa.tests.AssertTests1@546a03af]" name="arraysFailures_3" duration-ms="2483" started-at="2014-04-28T08:02:41Z" finished-at="2014-04-28T08:02:44Z">
          <exception class="java.lang.AssertionError">
            <message>
              <![CDATA[expected [[J@49c4ada8] but found [1]]]>
            </message>
            <full-stacktrace>
              <![CDATA[java.lang.AssertionError: expected [[J@49c4ada8] but found [1]
	at org.testng.Assert.fail(Assert.java:94)
	at org.testng.Assert.failNotEquals(Assert.java:494)
	at org.testng.Assert.assertArrayEquals(Assert.java:155)
	at org.testng.Assert.assertEquals(Assert.java:117)
	at org.testng.Assert.assertEquals(Assert.java:165)
	at qa.tests.AssertTests1.arraysFailures_3(AssertTests1.java:67)
	at sun.reflect.NativeMethodAccessorImpl.invoke0(Native Method)
	at sun.reflect.NativeMethodAccessorImpl.invoke(NativeMethodAccessorImpl.java:62)
	at sun.reflect.DelegatingMethodAccessorImpl.invoke(DelegatingMethodAccessorImpl.java:43)
	at java.lang.reflect.Method.invoke(Method.java:483)
	at org.testng.internal.MethodInvocationHelper.invokeMethod(MethodInvocationHelper.java:84)
	at org.testng.internal.Invoker.invokeMethod(Invoker.java:714)
	at org.testng.internal.Invoker.invokeTestMethod(Invoker.java:901)
	at org.testng.internal.Invoker.invokeTestMethods(Invoker.java:1231)
	at org.testng.internal.TestMethodWorker.invokeTestMethods(TestMethodWorker.java:127)
	at org.testng.internal.TestMethodWorker.run(TestMethodWorker.java:111)
	at java.util.concurrent.ThreadPoolExecutor.runWorker(ThreadPoolExecutor.java:1142)
	at java.util.concurrent.ThreadPoolExecutor$Worker.run(ThreadPoolExecutor.java:617)
	at java.lang.Thread.run(Thread.java:745)
]]>
            </full-stacktrace>
          </exception> <!-- java.lang.AssertionError -->
          <reporter-output>
          </reporter-output>
        </test-method> <!-- arraysFailures_3 -->
        <test-method status="PASS" signature="intArray_Issue4()[pri:0, instance:qa.tests.AssertTests1@546a03af]" name="intArray_Issue4" duration-ms="1016" started-at="2014-04-28T08:02:44Z" finished-at="2014-04-28T08:02:45Z">
          <reporter-output>
          </reporter-output>
        </test-method> <!-- intArray_Issue4 -->
        <test-method status="PASS" signature="int_Integer_Arrays()[pri:0, instance:qa.tests.AssertTests1@546a03af]" name="int_Integer_Arrays" duration-ms="1041" started-at="2014-04-28T08:02:45Z" finished-at="2014-04-28T08:02:46Z">
          <reporter-output>
          </reporter-output>
        </test-method> <!-- int_Integer_Arrays -->
        <test-method status="PASS" signature="noOrderFailure()[pri:0, instance:qa.tests.AssertTests1@546a03af]" name="noOrderFailure" duration-ms="2035" started-at="2014-04-28T08:02:46Z" finished-at="2014-04-28T08:02:48Z">
          <exception class="java.lang.AssertionError">
            <message>
              <![CDATA[Arrays not equal: [a, b, b] and [a, a, b]]]>
            </message>
            <full-stacktrace>
              <![CDATA[java.lang.AssertionError: Arrays not equal: [a, b, b] and [a, a, b]
	at org.testng.Assert.fail(Assert.java:94)
	at org.testng.Assert.failAssertNoEqual(Assert.java:713)
	at org.testng.Assert.assertEqualsNoOrder(Assert.java:703)
	at org.testng.Assert.assertEqualsNoOrder(Assert.java:735)
	at qa.tests.AssertTests1.noOrderFailure(AssertTests1.java:28)
	at sun.reflect.NativeMethodAccessorImpl.invoke0(Native Method)
	at sun.reflect.NativeMethodAccessorImpl.invoke(NativeMethodAccessorImpl.java:62)
	at sun.reflect.DelegatingMethodAccessorImpl.invoke(DelegatingMethodAccessorImpl.java:43)
	at java.lang.reflect.Method.invoke(Method.java:483)
	at org.testng.internal.MethodInvocationHelper.invokeMethod(MethodInvocationHelper.java:84)
	at org.testng.internal.Invoker.invokeMethod(Invoker.java:714)
	at org.testng.internal.Invoker.invokeTestMethod(Invoker.java:901)
	at org.testng.internal.Invoker.invokeTestMethods(Invoker.java:1231)
	at org.testng.internal.TestMethodWorker.invokeTestMethods(TestMethodWorker.java:127)
	at org.testng.internal.TestMethodWorker.run(TestMethodWorker.java:111)
	at java.util.concurrent.ThreadPoolExecutor.runWorker(ThreadPoolExecutor.java:1142)
	at java.util.concurrent.ThreadPoolExecutor$Worker.run(ThreadPoolExecutor.java:617)
	at java.lang.Thread.run(Thread.java:745)
]]>
            </full-stacktrace>
          </exception> <!-- java.lang.AssertionError -->
          <reporter-output>
          </reporter-output>
        </test-method> <!-- noOrderFailure -->
        <test-method status="PASS" signature="noOrderSuccess()[pri:0, instance:qa.tests.AssertTests1@546a03af]" name="noOrderSuccess" duration-ms="1212" started-at="2014-04-28T08:02:48Z" finished-at="2014-04-28T08:02:49Z">
          <reporter-output>
          </reporter-output>
        </test-method> <!-- noOrderSuccess -->
        <test-method status="PASS" signature="setsSuccess()[pri:0, instance:qa.tests.AssertTests1@546a03af]" name="setsSuccess" duration-ms="2801" started-at="2014-04-28T08:02:49Z" finished-at="2014-04-28T08:02:52Z">
          <reporter-output>
          </reporter-output>
        </test-method> <!-- setsSuccess -->
      </class> <!-- qa.tests.AssertTests1 -->
      <class name="qa.tests.AssertTests2">
        <test-method status="PASS" signature="arraysFailures_1()[pri:0, instance:qa.tests.AssertTests2@23223dd8]" name="arraysFailures_1" duration-ms="2488" started-at="2014-04-28T08:02:37Z" finished-at="2014-04-28T08:02:39Z">
          <exception class="java.lang.AssertionError">
            <message>
              <![CDATA[ expected [[J@4f83fd11] but found [[I@63607386]]]>
            </message>
            <full-stacktrace>
              <![CDATA[java.lang.AssertionError:  expected [[J@4f83fd11] but found [[I@63607386]
	at org.testng.Assert.fail(Assert.java:94)
	at org.testng.Assert.failNotEquals(Assert.java:494)
	at org.testng.Assert.assertArrayEquals(Assert.java:144)
	at org.testng.Assert.assertEquals(Assert.java:117)
	at org.testng.Assert.assertEquals(Assert.java:165)
	at qa.tests.AssertTests2.arraysFailures_1(AssertTests2.java:55)
	at sun.reflect.NativeMethodAccessorImpl.invoke0(Native Method)
	at sun.reflect.NativeMethodAccessorImpl.invoke(NativeMethodAccessorImpl.java:62)
	at sun.reflect.DelegatingMethodAccessorImpl.invoke(DelegatingMethodAccessorImpl.java:43)
	at java.lang.reflect.Method.invoke(Method.java:483)
	at org.testng.internal.MethodInvocationHelper.invokeMethod(MethodInvocationHelper.java:84)
	at org.testng.internal.Invoker.invokeMethod(Invoker.java:714)
	at org.testng.internal.Invoker.invokeTestMethod(Invoker.java:901)
	at org.testng.internal.Invoker.invokeTestMethods(Invoker.java:1231)
	at org.testng.internal.TestMethodWorker.invokeTestMethods(TestMethodWorker.java:127)
	at org.testng.internal.TestMethodWorker.run(TestMethodWorker.java:111)
	at java.util.concurrent.ThreadPoolExecutor.runWorker(ThreadPoolExecutor.java:1142)
	at java.util.concurrent.ThreadPoolExecutor$Worker.run(ThreadPoolExecutor.java:617)
	at java.lang.Thread.run(Thread.java:745)
]]>
            </full-stacktrace>
          </exception> <!-- java.lang.AssertionError -->
          <reporter-output>
          </reporter-output>
        </test-method> <!-- arraysFailures_1 -->
        <test-method status="PASS" signature="arraysFailures_2()[pri:0, instance:qa.tests.AssertTests2@23223dd8]" name="arraysFailures_2" duration-ms="1078" started-at="2014-04-28T08:02:39Z" finished-at="2014-04-28T08:02:40Z">
          <exception class="java.lang.AssertionError">
            <message>
              <![CDATA[expected [1] but found [[I@dac9561]]]>
            </message>
            <full-stacktrace>
              <![CDATA[java.lang.AssertionError: expected [1] but found [[I@dac9561]
	at org.testng.Assert.fail(Assert.java:94)
	at org.testng.Assert.failNotEquals(Assert.java:494)
	at org.testng.Assert.assertEquals(Assert.java:123)
	at org.testng.Assert.assertEquals(Assert.java:165)
	at qa.tests.AssertTests2.arraysFailures_2(AssertTests2.java:62)
	at sun.reflect.NativeMethodAccessorImpl.invoke0(Native Method)
	at sun.reflect.NativeMethodAccessorImpl.invoke(NativeMethodAccessorImpl.java:62)
	at sun.reflect.DelegatingMethodAccessorImpl.invoke(DelegatingMethodAccessorImpl.java:43)
	at java.lang.reflect.Method.invoke(Method.java:483)
	at org.testng.internal.MethodInvocationHelper.invokeMethod(MethodInvocationHelper.java:84)
	at org.testng.internal.Invoker.invokeMethod(Invoker.java:714)
	at org.testng.internal.Invoker.invokeTestMethod(Invoker.java:901)
	at org.testng.internal.Invoker.invokeTestMethods(Invoker.java:1231)
	at org.testng.internal.TestMethodWorker.invokeTestMethods(TestMethodWorker.java:127)
	at org.testng.internal.TestMethodWorker.run(TestMethodWorker.java:111)
	at java.util.concurrent.ThreadPoolExecutor.runWorker(ThreadPoolExecutor.java:1142)
	at java.util.concurrent.ThreadPoolExecutor$Worker.run(ThreadPoolExecutor.java:617)
	at java.lang.Thread.run(Thread.java:745)
]]>
            </full-stacktrace>
          </exception> <!-- java.lang.AssertionError -->
          <reporter-output>
          </reporter-output>
        </test-method> <!-- arraysFailures_2 -->
        <test-method status="PASS" signature="arraysFailures_3()[pri:0, instance:qa.tests.AssertTests2@23223dd8]" name="arraysFailures_3" duration-ms="2243" started-at="2014-04-28T08:02:40Z" finished-at="2014-04-28T08:02:42Z">
          <exception class="java.lang.AssertionError">
            <message>
              <![CDATA[expected [[J@3d0b2ed7] but found [1]]]>
            </message>
            <full-stacktrace>
              <![CDATA[java.lang.AssertionError: expected [[J@3d0b2ed7] but found [1]
	at org.testng.Assert.fail(Assert.java:94)
	at org.testng.Assert.failNotEquals(Assert.java:494)
	at org.testng.Assert.assertArrayEquals(Assert.java:155)
	at org.testng.Assert.assertEquals(Assert.java:117)
	at org.testng.Assert.assertEquals(Assert.java:165)
	at qa.tests.AssertTests2.arraysFailures_3(AssertTests2.java:69)
	at sun.reflect.NativeMethodAccessorImpl.invoke0(Native Method)
	at sun.reflect.NativeMethodAccessorImpl.invoke(NativeMethodAccessorImpl.java:62)
	at sun.reflect.DelegatingMethodAccessorImpl.invoke(DelegatingMethodAccessorImpl.java:43)
	at java.lang.reflect.Method.invoke(Method.java:483)
	at org.testng.internal.MethodInvocationHelper.invokeMethod(MethodInvocationHelper.java:84)
	at org.testng.internal.Invoker.invokeMethod(Invoker.java:714)
	at org.testng.internal.Invoker.invokeTestMethod(Invoker.java:901)
	at org.testng.internal.Invoker.invokeTestMethods(Invoker.java:1231)
	at org.testng.internal.TestMethodWorker.invokeTestMethods(TestMethodWorker.java:127)
	at org.testng.internal.TestMethodWorker.run(TestMethodWorker.java:111)
	at java.util.concurrent.ThreadPoolExecutor.runWorker(ThreadPoolExecutor.java:1142)
	at java.util.concurrent.ThreadPoolExecutor$Worker.run(ThreadPoolExecutor.java:617)
	at java.lang.Thread.run(Thread.java:745)
]]>
            </full-stacktrace>
          </exception> <!-- java.lang.AssertionError -->
          <reporter-output>
          </reporter-output>
        </test-method> <!-- arraysFailures_3 -->
        <test-method status="PASS" signature="intArray_Issue4()[pri:0, instance:qa.tests.AssertTests2@23223dd8]" name="intArray_Issue4" duration-ms="2437" started-at="2014-04-28T08:02:42Z" finished-at="2014-04-28T08:02:45Z">
          <reporter-output>
          </reporter-output>
        </test-method> <!-- intArray_Issue4 -->
        <test-method status="PASS" signature="int_Integer_Arrays()[pri:0, instance:qa.tests.AssertTests2@23223dd8]" name="int_Integer_Arrays" duration-ms="2724" started-at="2014-04-28T08:02:45Z" finished-at="2014-04-28T08:02:48Z">
          <reporter-output>
          </reporter-output>
        </test-method> <!-- int_Integer_Arrays -->
        <test-method status="PASS" signature="noOrderFailure()[pri:0, instance:qa.tests.AssertTests2@23223dd8]" name="noOrderFailure" duration-ms="1885" started-at="2014-04-28T08:02:48Z" finished-at="2014-04-28T08:02:50Z">
          <exception class="java.lang.AssertionError">
            <message>
              <![CDATA[Arrays not equal: [a, b, b] and [a, a, b]]]>
            </message>
            <full-stacktrace>
              <![CDATA[java.lang.AssertionError: Arrays not equal: [a, b, b] and [a, a, b]
	at org.testng.Assert.fail(Assert.java:94)
	at org.testng.Assert.failAssertNoEqual(Assert.java:713)
	at org.testng.Assert.assertEqualsNoOrder(Assert.java:703)
	at org.testng.Assert.assertEqualsNoOrder(Assert.java:735)
	at qa.tests.AssertTests2.noOrderFailure(AssertTests2.java:30)
	at sun.reflect.NativeMethodAccessorImpl.invoke0(Native Method)
	at sun.reflect.NativeMethodAccessorImpl.invoke(NativeMethodAccessorImpl.java:62)
	at sun.reflect.DelegatingMethodAccessorImpl.invoke(DelegatingMethodAccessorImpl.java:43)
	at java.lang.reflect.Method.invoke(Method.java:483)
	at org.testng.internal.MethodInvocationHelper.invokeMethod(MethodInvocationHelper.java:84)
	at org.testng.internal.Invoker.invokeMethod(Invoker.java:714)
	at org.testng.internal.Invoker.invokeTestMethod(Invoker.java:901)
	at org.testng.internal.Invoker.invokeTestMethods(Invoker.java:1231)
	at org.testng.internal.TestMethodWorker.invokeTestMethods(TestMethodWorker.java:127)
	at org.testng.internal.TestMethodWorker.run(TestMethodWorker.java:111)
	at java.util.concurrent.ThreadPoolExecutor.runWorker(ThreadPoolExecutor.java:1142)
	at java.util.concurrent.ThreadPoolExecutor$Worker.run(ThreadPoolExecutor.java:617)
	at java.lang.Thread.run(Thread.java:745)
]]>
            </full-stacktrace>
          </exception> <!-- java.lang.AssertionError -->
          <reporter-output>
          </reporter-output>
        </test-method> <!-- noOrderFailure -->
        <test-method status="PASS" signature="noOrderSuccess()[pri:0, instance:qa.tests.AssertTests2@23223dd8]" name="noOrderSuccess" duration-ms="532" started-at="2014-04-28T08:02:50Z" finished-at="2014-04-28T08:02:50Z">
          <reporter-output>
          </reporter-output>
        </test-method> <!-- noOrderSuccess -->
        <test-method status="PASS" signature="setsSuccess()[pri:0, instance:qa.tests.AssertTests2@23223dd8]" name="setsSuccess" duration-ms="1673" started-at="2014-04-28T08:02:50Z" finished-at="2014-04-28T08:02:52Z">
          <reporter-output>
          </reporter-output>
        </test-method> <!-- setsSuccess -->
      </class> <!-- qa.tests.AssertTests2 -->
    </test> <!-- Main Test Group -->
  </suite> <!-- Main Test Suite -->
</testng-results>
